Workbook

Sheet Read Me
A1: Target Media List (TML): October 2026
A3: Prepared | B3: 4 Oct 2026, from online research plus the media lists in this repository.
A4: Scope | B4: Alcobev + F&B (Six Brothers, DeVANS, Mast Banarasi Paan); Devyani Jaipuria only: Lifestyle, Celebrity & Society, and Luxury/Art/Business tabs; DHS Gurugram (Delhi NCR education).
A5: Round 2 | B5: Added names found through new online research that are not in your lists. Their Contact Source reads 'New research: contact to source'; phone and email are left blank for you to fill. DHS tab now also includes sports journalists (marked SPORTS in Notes) for the sports-complex angle.
A6: Listicles | B6: See also the 'Alcobev Listicles - Verify' tab: brand lists whose author was not visible, with links to check the byline (yellow column to fill). Alcobev + F&B tab, column N: YES = confirmed brand listicles (name highlighted); LIKELY = brand round-ups; OUTLET = publication runs brand lists, pitch via the editor; VENUE = lists bars/restaurants, not brands.
A7: Method | B7: Each name was checked online for a current role at the outlet and recent work on the same beat (2026 bylines, mastheads, appointment notices). Phone and email were taken only from the existing lists in this repo, never guessed.
A8: Contacts | B8: Blank phone or email means the person is not in your lists. Source contacts via your PR database or LinkedIn. Emails tied to an old employer were removed and are listed on the 'Moved - Do Not Use' tab.
A9: Limits | B9: Publisher websites could not be opened directly from this environment, so verification relied on search results (author pages, Muck Rack, LinkedIn, trade press). Rows marked 'To confirm' need a quick call or email check before pitching.
A10: Gaps | B10: No named Delhi Times (TOI) society writer or HT Gurugram schools reporter could be confirmed online; worth sourcing through your network.
A12: Verification status
A13: Verified - active 2026 | B13: A 2026-dated byline, column, appointment or public appearance at this outlet on this beat.
A14: Verified - current role | B14: Current role confirmed by masthead, profile or appointment notice; no 2026-dated byline found.
A15: To confirm | B15: Partial or older evidence only. Confirm before pitching.
A16: Moved - updated | B16: Your lists had this person at another outlet or desk; the row shows the current one.
A18: Summary
A19: Tab | B19: Total | C19: Verified - active 2026 | D19: Verified - current role | E19: To confirm | F19: Moved - updated
A20: Alcobev + F&B | B20: =COUNTA('Alcobev + F&B'!$B$5:$B$48) | C20: =COUNTIF('Alcobev + F&B'!$J$5:$J$48,"Verified - active 2026") | D20: =COUNTIF('Alcobev + F&B'!$J$5:$J$48,"Verified - current role") | E20: =COUNTIF('Alcobev + F&B'!$J$5:$J$48,"To confirm") | F20: =COUNTIF('Alcobev + F&B'!$J$5:$J$48,"Moved - updated")
A21: Devyani - Lifestyle | B21: =COUNTA('Devyani - Lifestyle'!$B$5:$B$28) | C21: =COUNTIF('Devyani - Lifestyle'!$J$5:$J$28,"Verified - active 2026") | D21: =COUNTIF('Devyani - Lifestyle'!$J$5:$J$28,"Verified - current role") | E21: =COUNTIF('Devyani - Lifestyle'!$J$5:$J$28,"To confirm") | F21: =COUNTIF('Devyani - Lifestyle'!$J$5:$J$28,"Moved - updated")
A22: Devyani - Celebrity & Society | B22: =COUNTA('Devyani - Celebrity & Society'!$B$5:$B$13) | C22: =COUNTIF('Devyani - Celebrity & Society'!$J$5:$J$13,"Verified - active 2026") | D22: =COUNTIF('Devyani - Celebrity & Society'!$J$5:$J$13,"Verified - current role") | E22: =COUNTIF('Devyani - Celebrity & Society'!$J$5:$J$13,"To confirm") | F22: =COUNTIF('Devyani - Celebrity & Society'!$J$5:$J$13,"Moved - updated")
A23: Devyani - Luxury, Art, Biz | B23: =COUNTA('Devyani - Luxury, Art, Biz'!$B$5:$B$18) | C23: =COUNTIF('Devyani - Luxury, Art, Biz'!$J$5:$J$18,"Verified - active 2026") | D23: =COUNTIF('Devyani - Luxury, Art, Biz'!$J$5:$J$18,"Verified - current role") | E23: =COUNTIF('Devyani - Luxury, Art, Biz'!$J$5:$J$18,"To confirm") | F23: =COUNTIF('Devyani - Luxury, Art, Biz'!$J$5:$J$18,"Moved - updated")
A24: DHS - Delhi NCR Education | B24: =COUNTA('DHS - Delhi NCR Education'!$B$5:$B$47) | C24: =COUNTIF('DHS - Delhi NCR Education'!$J$5:$J$47,"Verified - active 2026") | D24: =COUNTIF('DHS - Delhi NCR Education'!$J$5:$J$47,"Verified - current role") | E24: =COUNTIF('DHS - Delhi NCR Education'!$J$5:$J$47,"To confirm") | F24: =COUNTIF('DHS - Delhi NCR Education'!$J$5:$J$47,"Moved - updated")
A25: Total | B25: =SUM(B20:B24) | C25: =SUM(C20:C24) | D25: =SUM(D20:D24) | E25: =SUM(E20:E24) | F25: =SUM(F20:F24)

Sheet Alcobev + F&B
A1: Alcobev + F&B
A2: Alcobev, spirits, bars and F&B business journalists. Brands: Six Brothers Distilleries (mahua), DeVANS Modern Breweries, Mast Banarasi Paan. Column N flags writers who do brand listicles (highlighted names = confirmed); filter column N to see them.
A4: S.No | B4: Journalist Name | C4: Designation | D4: Organisation | E4: Beat / Vertical | F4: City | G4: Phone | H4: Email | I4: Contact Source (your lists) | J4: Verification Status | K4: Latest Activity Found | L4: Evidence Link | M4: Notes / Brand Fit | N4: Brand Listicles? | O4: Listicle Evidence
A5: 1 | B5: Bishan Kumar | C5: Editor-in-Chief | D5: Spiritz Magazine (Blue Ink Media) | E5: Alcobev trade: spirits, beer, bars, hospitality | F5: New Delhi | I5: Not in lists | J5: Verified - current role | K5: Listed as Editor-in-Chief on company directory (spiritz.in domain) | L5: https://www.zoominfo.com/p/Bishan-Kumar/9350175409 | M5: Specialist alcobev trade title. Fit: Six Brothers (mahua revival), DeVANS launches and awards. | N5: No evidence found
A6: 2 | B6: Rajesh Kumar Chaubey | C6: Chief Editor | D6: Aabkari Times | E6: Excise policy and alcobev industry (Hindi/English monthly) | F6: Prayagraj | I6: Not in lists | J6: Verified - current role | K6: Named Chief Editor on editorial policy page; site publishing in 2026 (Mar 2026 article) | L6: https://aabkaritimes.com/editorial-policy/ | M6: Fit: DeVANS (policy, state markets), mahua heritage-liquor policy angle. | N6: No evidence found
A7: 3 | B7: Prem Shankar Mishra | C7: Founder and Managing Editor | D7: Aabkari Times | E7: Excise policy and alcobev industry | F7: Prayagraj | I7: Not in lists | J7: Verified - current role | K7: Founder and Managing Editor per masthead and LinkedIn | L7: https://www.linkedin.com/in/ps-mishra-772a0328/ | M7: Same outlet as above; pitch one of the two, not both. | N7: No evidence found
A8: 4 | B8: Aneeka Chatterjee | C8: Correspondent | D8: Business Standard | E8: Consumer, FMCG and alcobev business | F8: Bengaluru | G8: 8240053834 | H8: aneeka.chatterjee@bsmail.in | I8: Anna's Health Media List; NH Media list | J8: Verified - active 2026 | K8: Byline: 'Results preview: Alcobev industry growth may have cooled in Q3FY26' (15 Jan 2026) | L8: https://www.business-standard.com/industry/news/results-preview-alcobev-industry-growth-may-have-cooled-in-q3fy26-126011501168_1.html | M8: Business-side alcobev. Fit: DeVANS, Six Brothers once founders are confirmed. | N8: No evidence found
A9: 5 | B9: Akshara Srivastava | C9: Correspondent (consumption beat) | D9: Business Standard | E9: FMCG, beverages, retail, luxury, hospitality | F9: New Delhi | I9: Not in lists | J9: Verified - active 2026 | K9: Author page shows 2026 stories on FMCG, beverages, premiumisation | L9: https://www.business-standard.com/author/akshara-srivastava/page-2 | M9: Fit: Mast Banarasi Paan (organised F&B, fundraise), alcobev premiumisation. | N9: No evidence found
A10: 6 | B10: Suneera Tandon | C10: Reporter | D10: Mint | E10: Consumer goods, retail, food and beverages | F10: New Delhi | G10: 9810445443 | H10: suneera.tandon@livemint.com; suneera.t@htlive.com | I10: A & M Media List; Sports Media List PDF | J10: Verified - active 2026 | K10: 2026 Mint bylines incl. 'India's FMCG sector is entering 2026 betting on volumes, not prices' | L10: https://muckrack.com/suneera-tandon | M10: Fit: Mast Banarasi Paan INR 50 cr FY27 and fundraise story; alcobev business. | N10: No evidence found
A11: 7 | B11: Tarannum Manjul | C11: Writer (designation to confirm) | D11: BW Retail World (BW Businessworld) | E11: Food and beverage, alcobev retail | F11: New Delhi | I11: Not in lists | J11: Verified - active 2026 | K11: Byline: 'India Alcobev Trends 2026: Premiumisation, Moderation, Reform' | L11: https://bwretailworld.com/food-beverage/india-alcobev-trends-2026-premiumisation-moderation-reform | M11: Fit: DeVANS, Six Brothers, Mast Banarasi Paan (F&B retail). | N11: No evidence found
A12: 8 | B12: Alka Jain | C12: Journalist | D12: Outlook Business | E12: Industry, alcobev market | F12: New Delhi | I12: Real Estate Media List (name only, no contact) | J12: To confirm | K12: Byline: 'India's Alcobev Market Splits Into A K-Shaped Growth Story' (date to confirm) | L12: https://www.outlookbusiness.com/industry/indias-alcobev-market-splits-into-a-k-shaped-growth-story | M12: Your list has her as Outlook Publishing Senior Subeditor with no contact. | N12: No evidence found
A13: 9 | B13: Saptopriya Ghosal | C13: Junior Writer | D13: Restaurant India (Franchise India Media) | E13: Spirits, whisky, bars, F&B | F13: New Delhi | I13: Not in lists | J13: Verified - active 2026 | K13: Byline: '7 Indian Spirits Most Drinkers Outside India Have Never Heard Of' (8 Sep 2026), covers mahua | L13: https://www.restaurantindia.in/article/7-indian-spirits-most-drinkers-outside-india-have-never-heard-of.17178 | M13: Strong fit: Six Brothers mahua heritage angle; DeVANS whisky/beer. | N13: YES - brand listicles | O13: 'Top Craft & Boutique Alcohol Brands to Watch in 2026'; '7 Indian Spirits Most Drinkers Outside India Have Never Heard Of' (Sep 2026)
A14: 10 | B14: Vijetha Iyer | C14: Writer | D14: Restaurant India (Franchise India Media) | E14: Bars, cocktail culture | F14: New Delhi | I14: Not in lists | J14: Verified - active 2026 | K14: Byline: 'How India's Cocktail Culture is Redefining the Modern Bar Experience' (23 Jul 2026) | L14: https://www.restaurantindia.in/article/how-indias-cocktail-culture-is-redefining-the-modern-bar-experience.16809 | M14: Fit: Six Brothers (mahua in cocktails), DeVANS gin/RTD. | N14: No evidence found
A15: 11 | B15: Ritu Marya | C15: Editor-in-Chief | D15: Franchise India Media (Entrepreneur India, Restaurant India, Indian Retailer) | E15: F&B business, franchising, restaurants | F15: New Delhi | I15: Not in lists | J15: Verified - current role | K15: Leads editorial for Entrepreneur India, restaurantindia.in, indianretailer.com | L15: https://www.franchiseindia.com/insights/en/news/indian-restaurant-congress-goes-global-with-first-international-edition-in-london.58927 | M15: Fit: Mast Banarasi Paan founder profile, franchise-led growth. | N15: OUTLET runs brand listicles | O15: Restaurant India and Indian Retailer run 'Top 10 / Top 8' brand lists (gin, mahua incl. Six Brothers, whisky, rum); pitch via editor
A16: 12 | B16: Himanshi Kaushik | C16: News Writer | D16: FranchiseTV / Indian Retailer | E16: F&B and franchise brands | F16: New Delhi | I16: Not in lists | J16: Verified - active 2026 | K16: 2026 bylines on food franchise trends (FranchiseTV) | L16: https://indianretailer.com/franchisetv/author/himanshi-kaushik | M16: Fit: Mast Banarasi Paan (outlet already covered its 600-store plan). | N16: OUTLET runs brand listicles | O16: Indian Retailer (her outlet) runs 'Top Mahua Brands' and 'Top 8 Indian Gin Brands' lists; author not credited
A17: 13 | B17: Ruchika Jha | C17: Copy Editor | D17: Images Business of Food | E17: Food business, foodservice, HoReCa | F17: New Delhi | I17: Not in lists | J17: Verified - current role | K17: Named Copy Editor; outlet covered Mast Banarasi Paan's 400-outlet milestone in 2026 | L17: https://www.businessoffood.in/mast-banarasi-paan-charts-aggressive-growth-crossing-400-outlets-explores-fresh-capital/ | M17: Fit: Mast Banarasi Paan follow-ups (premium gold/silver paan angle). | N17: No evidence found
A18: 14 | B18: Rajlakshmi Dastidar | C18: Writer | D18: Slurrp (HT Media) | E18: Whisky, spirits, food culture | F18: Kolkata/Delhi (to confirm) | I18: Not in lists | J18: Verified - active 2026 | K18: Byline: 'International Whisky Day 2026: India's New Wave Whisky Culture' (27 Mar 2026) | L18: https://www.slurrp.com/article/international-whisky-day-2026-experts-on-the-new-whisky-culture-in-india-1774577006830 | M18: Fit: DeVANS GianChand single malt; Six Brothers. | N18: LIKELY - brand roundups | O18: 'International Whisky Day 2026' expert round-up naming brands
A19: 15 | B19: Shireen Jamooji | C19: Writer | D19: Slurrp (HT Media) | E19: Spirits and cocktails | I19: Not in lists | J19: Verified - active 2026 | K19: Byline: 'World Whisky Day 2026: Whisky Cocktails & Mango Moments' (16 May 2026) | L19: https://www.slurrp.com/article/world-whisky-day-2026-whisky-cocktails-amp-mango-moments-when-the-king-of-fruits-meets-the-king-of-spirits-1778850851459 | M19: Fit: DeVANS, Six Brothers. | N19: LIKELY - brand roundups | O19: 'World Whisky Day 2026: Whisky Cocktails & Mango Moments' (brand and cocktail picks)
A20: 16 | B20: Parag A Shastry | C20: Contributor | D20: Slurrp (HT Media) | E20: Cocktails, bar culture, local ingredients | I20: Not in lists | J20: Verified - active 2026 | K20: Byline: 'The Mindful Pour: Inside India's New Cocktail Consciousness' (6 May 2026) | L20: https://www.slurrp.com/article/the-mindful-pour-inside-indias-new-cocktail-consciousness-1778067928872 | M20: Fit: Six Brothers (local-ingredient, heritage spirit). | N20: No evidence found
A21: 17 | B21: Nikhil Merchant | C21: Freelance food, spirits and luxury writer | D21: Slurrp, Condé Nast Traveller, Financial Express, The Nod Mag | E21: Spirits, F&B, hospitality, luxury | F21: Mumbai | I21: Not in lists | J21: Verified - active 2026 | K21: Byline: 'India's Gin Renaissance Enters Its Second Act' (Slurrp, 30 Sep 2026); 'The New Spirit of Asia' (Aug 2026) | L21: https://www.slurrp.com/article/indias-gin-renaissance-enters-its-second-act-1790770816838 | M21: Strong fit: Six Brothers (Indian craft spirits going global), DeVANS gin. | N21: No evidence found
A22: 18 | B22: Anindita Ghosh | C22: Editor | D22: OT Eats (Outlook Traveller) | E22: Food and drink | F22: New Delhi | I22: Not in lists | J22: Verified - current role | K22: Named OT Eats Editor; outlet published a mahua heritage-spirits guide | L22: https://oteats.outlooktraveller.com/about-us | M22: Fit: Six Brothers (OT Eats already covers mahua). | N22: OUTLET runs brand listicles | O22: OT Eats / OT Pours publish 'best brands' lists (mahua, homegrown gins, Indian rums); pitch via editor
A23: 19 | B23: Abhya Adlakha | C23: Writer | D23: Esquire India | E23: Food and drinks, restaurants and bars | I23: Not in lists | J23: Verified - active 2026 | K23: Byline: 'The Best New Restaurants and Bars in India in 2026 (So Far)' (22 Apr 2026) | L23: https://www.esquireindia.co.in/food-and-drinks/what-to-eat/the-best-new-restaurants-and-bars-in-india-in-2026-so-far | M23: Fit: DeVANS, Six Brothers (bar listings and launches). | N23: YES - brand listicles | O23: 'Best Homegrown Rums to Try in 2026' (Esquire India); also monthly bar/restaurant Hotlists
A24: 20 | B24: Geetika Sachdev | C24: Contributor | D24: The Nod Mag | E24: Delhi NCR restaurants, bars, menus | F24: Delhi NCR | I24: Not in lists | J24: Verified - active 2026 | K24: Monthly Delhi restaurant and bar guides (Jun and Jul 2026) | L24: https://thenodmag.com/author/geetika-sachdev | M24: Fit: Mast Banarasi Paan (Delhi NCR outlets), Six Brothers bar placements. | N24: VENUE lists only | O24: Monthly Delhi bars/restaurants lists, not brand lists
A25: 21 | B25: Poulomi Deb | C25: Senior Correspondent | D25: Time Out Delhi | E25: Delhi food, bars, culture | F25: New Delhi | I25: Not in lists | J25: Verified - active 2026 | K25: Time Out profile; covered India Art Fair 2026 (Feb 2026) | L25: https://www.timeout.com/profile/poulomi-deb | M25: Fit: Delhi launches for all F&B and alcobev brands; also art (Devyani). | N25: VENUE lists only | O25: Time Out 'best bars' lists
A26: 22 | B26: Nayantara Singh | C26: Senior Editor | D26: Time Out India | E26: Food, drink, city culture | I26: Not in lists | J26: Verified - current role | K26: Time Out profile lists her as Senior Editor, Time Out India | L26: https://www.timeout.com/profile/nayantara-singh | M26: Fit: 30 Best Bars India coverage; DeVANS, Six Brothers. | N26: VENUE lists only | O26: Time Out 'best bars' lists
A27: 23 | B27: Anisha Khole | C27: Writer | D27: Local Samosa | E27: Brand stories, homegrown brands | I27: Not in lists | J27: Verified - active 2026 | K27: Byline: Mohulo gin (mahua flower) brand story (26 Mar 2026) | L27: https://www.localsamosa.com/business/mohulo-gin-brand-story-11226236 | M27: Strong fit: Six Brothers mahua brand story. | N27: No evidence found
A28: 24 | B28: Vir Sanghvi | C28: Columnist (Rude Food) | D28: Hindustan Times / HT Brunch | E28: Food and drink | F28: New Delhi | I28: Not in lists | J28: Verified - active 2026 | K28: Rude Food column, e.g. 'Why the avocado is like butter, but better' (11 Sep 2026) | L28: https://muckrack.com/vir-sanghvi/articles | M28: Top-tier food voice. Fit: Six Brothers heritage story; Mast Banarasi Paan (paan as dessert). | N28: No evidence found
A29: 25 | B29: Sourish Bhattacharyya | C29: Food columnist and restaurant critic (freelance) | D29: Freelance; co-founder, Delhi Gourmet Club | E29: Indian food culture, heritage food and drink | F29: New Delhi | I29: Not in lists | J29: Verified - active 2026 | K29: Moderated Food and Tourism panel at Delhi Food Awards 2026; Godrej Food Trends Report 2026 launch | L29: https://www.outlooktraveller.com/News/delhi-food-awards-2026-celebrates-culinary-heritage-community-and-the-future-of-food-in-the-capital | M29: Fit: Mast Banarasi Paan (Banarasi paan heritage), Six Brothers. | N29: No evidence found
A30: 26 | B30: Magandeep Singh | C30: Columnist ('Between sips'); sommelier | D30: The Hindu (columnist); multiple titles | E30: Wine and spirits | F30: New Delhi | I30: Not in lists | J30: Verified - active 2026 | K30: Column 'Between sips: New red on the block' in The Hindu (29 Jan 2026) | L30: https://muckrack.com/magandeep-singh/articles | M30: Fit: DeVANS, Six Brothers (spirits critique and tasting). | N30: No evidence found
A31: 27 | B31: Rupali Dean | C31: Freelance food and travel writer | D31: Sunday Guardian, Elle Gourmet, Robb Report India | E31: Food, restaurants, travel | F31: New Delhi | I31: Not in lists | J31: Verified - active 2026 | K31: Byline in Sunday Guardian (4 Oct 2026) | L31: https://sundayguardianlive.com/feature/cinnamon-life-at-sri-lankas-city-of-dreams-a-fairytale-written-for-two-298239 | M31: Fit: Mast Banarasi Paan premium paan; Six Brothers. | N31: No evidence found
A32: 28 | B32: Aasheesh Sharma | C32: Digital Editor | D32: Outlook | E32: Food and lifestyle | F32: New Delhi | G32: 9811736051 | I32: Sports Media List PDF (phone only; HT email outdated) | J32: Moved - updated | K32: LinkedIn shows Digital Editor, Outlook; previously HT Brunch (your list still has him at HT) | L32: https://www.linkedin.com/in/aasheesh-sharma/ | M32: Do not use aasheesh.sharma@hindustantimes.com. Mobile is from the old list; confirm. | N32: No evidence found
A33: 29 | B33: Meher Mirza | C33: Food columnist | D33: NDTV Food (freelance) | E33: Food writing | F33: Mumbai | I33: Not in lists | J33: To confirm | K33: Author profile lists her as NDTV food columnist; no 2026 byline found | L33: https://www.lonelyplanet.com/authors/meher-mirza | M33: Confirm she is still writing before pitching. | N33: No evidence found
A34: 30 | B34: Ratna Bhushan | C34: Journalist (hospitality, retail, e-commerce) | D34: The Economic Times | E34: QSR and cafe chains, hospitality, consumer | F34: New Delhi | I34: New research: contact to source | J34: Verified - current role | K34: Muck Rack: ET journalist covering hospitality and retail, writes on QSR and cafe chains | L34: https://muckrack.com/ratna-bhushan/articles | M34: Fit: Mast Banarasi Paan (franchise expansion, fundraise). | N34: No evidence found
A35: 31 | B35: Smita Balram | C35: Journalist (liquor and spirits) | D35: The Economic Times (BrandEquity, ETRetail) | E35: Alcobev companies: AB InBev, Diageo, United Spirits | I35: New research: contact to source | J35: To confirm | K35: Muck Rack lists ET liquor and spirits coverage; no 2026 byline confirmed | L35: https://muckrack.com/smita-balram/articles | M35: Fit: DeVANS business and brand news. Confirm she is still on the beat. | N35: No evidence found
A36: 32 | B36: Devika Singh | C36: Freelance business journalist (ex-Moneycontrol, FE, Business Today) | D36: Freelance | E36: FMCG, consumer, liquor | I36: New research: contact to source | J36: Verified - current role | K36: Muck Rack: wrote on AB InBev entering whisky in India; consumer and FMCG coverage | L36: https://muckrack.com/devika-singh-3/articles | M36: Fit: DeVANS, Six Brothers (business of spirits). | N36: No evidence found
A37: 33 | B37: Miona Madsen | C37: Writer | D37: The Spirits Business (UK) | E37: Global spirits incl. Indian whisky | F37: London | I37: New research: contact to source | J37: Verified - active 2026 | K37: Byline: 'Top 10 biggest-selling Indian whisky Brand Champions' (12 Jun 2026) | L37: https://www.thespiritsbusiness.com/2026/06/top-10-biggest-selling-indian-whisky-brand-champions/ | M37: International trade title. Fit: Six Brothers 'mahua going global like tequila' story. | N37: YES - brand listicles | O37: 'Top 10 biggest-selling Indian whisky Brand Champions' (Jun 2026)
A38: 34 | B38: Diya Kohli | C38: Director of Features and Special Projects | D38: Condé Nast Traveller India | E38: Food and dining, features | F38: New Delhi | I38: New research: contact to source | J38: To confirm | K38: Muck Rack lists role and food/dining beat; no 2026 byline confirmed | L38: https://muckrack.com/diya-kohli/articles | M38: Fit: Six Brothers (heritage spirit travel story), Mast Banarasi Paan. | N38: No evidence found
A39: 35 | B39: Karina Acharya | C39: Food writer | D39: Condé Nast Traveller India | E39: Restaurants, Delhi food scene | F39: New Delhi | I39: New research: contact to source | J39: To confirm | K39: Listed on CNT India's Muck Rack page as food writer covering new Delhi restaurants (2026) | L39: https://muckrack.com/media-outlet/cntraveller-india | M39: Fit: Mast Banarasi Paan Delhi NCR outlets. | N39: VENUE lists only | O39: New Delhi restaurant round-ups
A40: 36 | B40: Ananya Desai | C40: Freelance writer | D40: Condé Nast Traveller India | E40: Food and beverage, travel | I40: New research: contact to source | J40: To confirm | K40: Muck Rack lists F&B coverage for CNT India | L40: https://muckrack.com/ananya-desai/articles | M40: Confirm before pitching. | N40: No evidence found
A41: 37 | B41: Pushpesh Pant | C41: Food columnist and historian | D41: Hindustan Times (columnist) | E41: Indian food history and culture | F41: New Delhi | I41: New research: contact to source | J41: Verified - current role | K41: Muck Rack lists HT food columns | L41: https://muckrack.com/pushpesh-pant/articles | M41: Strong fit: Mast Banarasi Paan (paan heritage), mahua history for Six Brothers. | N41: No evidence found
...

Sheet Alcobev Listicles - Verify
A1: Alcobev Listicles: Outlets to Verify
A2: Brand listicles found online where the author byline was not visible. Open the link to read the byline, then add the writer to the Alcobev + F&B tab.
A4: S.No | B4: Outlet | C4: Article Title | D4: Date | E4: Brands Covered | F4: Author Status | G4: Article Link | H4: Author Name (fill in)
A5: 1 | B5: Business Today (Lifestyle, Food & Drinks) | C5: World Gin Day 2026: The best Indian and international gins to pour, sip, and savour this year | D5: 13 Jun 2026 | E5: Indian craft gins + international gins | F5: Search snippet suggests an author first-named 'Sonali'; not confirmed | G5: https://www.businesstoday.in/lifestyle/food-drinks/story/world-gin-day-2026-the-best-indian-and-international-gins-to-pour-sip-and-savour-this-year-536550-2026-06-13
A6: 2 | B6: Elle India | C6: Hailing From Uttarakhand To Meghalaya, These 8 Homegrown Gin Labels Celebrate India's Regional Ingredients | D6: World Gin Day (date on page) | E6: 8 homegrown Indian gins | F6: Byline not visible in search | G6: https://elle.in/?p=233106
A7: 3 | B7: Elle India | C7: #WorldGinDay: 5 Homegrown Labels That Are Taking The Indian Gin Industry By Storm | D7: Older (date on page) | E7: 5 homegrown Indian gins | F7: Byline not visible in search | G7: https://elle.in/?p=127930
A8: 4 | B8: Indian Retailer | C8: Top Mahua Brands in India: Discover the Tribal Spirit of India | D8: Date on page | E8: Mahua brands incl. Six Brothers Mahura, DesmondJi, Mah | F8: Byline not visible in search. Already features Six Brothers | G8: https://indianretailer.com/article/retail-business/consumer-trends/top-mahua-brands-india-discover-tribal-spirit-india
A9: 5 | B9: Indian Retailer | C9: Celebrate Gin Day with the Top 8 Indian Gin Brands in India | D9: Date on page | E9: 8 Indian gins | F9: Byline not visible in search | G9: https://indianretailer.com/article/retail-business/consumer-trends/celebrate-gin-day-top-8-indian-gin-brands-india
A10: 6 | B10: Indian Retailer | C10: Top-Rated Rum Brands to Sip on This National Rum Day | D10: Date on page | E10: Rum brands | F10: Byline not visible in search | G10: https://indianretailer.com/article/retail-business/consumer-trends/top-rated-rum-brands-sip-national-rum-day
A11: 7 | B11: Outlook Traveller (OT Pours) | C11: 8 Best Indian Rums To Add To Your Home Bar In 2026 | D11: 17 Jul 2026 | E11: Camikara, Neoli, Pipa, Sitara and more | F11: Credited to 'OT Staff'; pitch OT Eats/OT Pours editor Anindita Ghosh | G11: https://www.outlooktraveller.com/ot-pours/8-premium-indian-rums-every-rum-lover-should-try
A12: 8 | B12: Outlook Traveller (OT Eats) | C12: World Rum Day 2025: 8 Indian Rums That Should Be On Your Radar | D12: 7 Sep 2025 | E12: 8 Indian rums | F12: Credited to 'OT Staff' | G12: https://oteats.outlooktraveller.com/features/guides/world-rum-day-2025-8-indian-rums-that-should-be-on-your-radar
A13: 9 | B13: Curly Tales | C13: 13 New Alcohol Launches In India Featuring Mango-Infused Rum, Japanese-Style Whisky & More | D13: 2026 (date on page) | E13: New spirit launches (recurring 'new launches' series) | F13: Possibly Mallika Khurana; not confirmed. Founder-editor: Kamiya Jani | G13: https://curlytales.com/india/food/new-alcohol-launches-in-india-featuring-mango-infused-rum-japanese-style-whisky-more/
A14: 10 | B14: Curly Tales | C14: From Agave To Aperitifs, 19 Top Brands That Defined India's Drinking Culture In 2025 | D14: Dec 2025 / Jan 2026 | E14: 19 alcohol brands | F14: Byline not visible in search | G14: https://curlytales.com/india/food/from-agave-to-aperitifs-top-brands-that-defined-indias-drinking-culture-in/
A15: 11 | B15: Restaurant India | C15: Top Indian Craft Rum Brands Gaining Attention in 2026 | D15: 2026 | E15: Indian craft rums | F15: Byline not visible in search (Saptopriya Ghosal and Mahak Sharma write similar lists here) | G15: https://www.restaurantindia.in/article/top-indian-craft-rum-brands-gaining-attention-in-2026.15338
A16: 12 | B16: Restaurant India | C16: Best Whisky in India 2026: Top 20 Whisky and Whiskey Brands With Price | D16: 2026 update | E16: 20 whisky brands | F16: Byline not visible in search | G16: https://www.restaurantindia.in/article/top-20-trendy-whiskeys-you-must-try-once.13499
... A20: 16 | B20: Outlook Luxe | C20: 14+ New Spirit Launches To Celebrate The Festive Season | D20: Festive season (date on page) | E20: New spirit launches | F20: Byline not visible in search | G20: https://luxe.outlookindia.com/food-travel/14-new-spirit-launches-to-celebrate-the-festive-season

Sheet Devyani - Lifestyle
A1: Devyani - Lifestyle
A2: FOR DEVYANI JAIPURIA ONLY. National lifestyle and women's titles for her personal-branding narrative.
A4: S.No | B4: Journalist Name | C4: Designation | D4: Organisation | E4: Beat / Vertical | F4: City | G4: Phone | H4: Email | I4: Contact Source (your lists) | J4: Verification Status | K4: Latest Activity Found | L4: Evidence Link | M4: Notes / Brand Fit
A5: 1 | B5: Jamal Shaikh | C5: National Editor, Brunch and New Media Initiatives | D5: Hindustan Times (HT Brunch) | E5: Lifestyle, culture, people | F5: New Delhi | I5: Not in lists | J5: Verified - active 2026 | K5: Active as HT Brunch editor; contributed to The Voice of Fashion (Jun 2026) | L5: https://muckrack.com/jamal-shaikh/articles | M5: Fit: Devyani Brunch cover or profile (art collector, mother of three, entrepreneur).
A6: 2 | B6: Rochelle Pinto | C6: Head of Editorial Content | D6: Vogue India | E6: Fashion, culture, women | F6: Mumbai | I6: Not in lists | J6: Verified - active 2026 | K6: Head of Editorial Content credited on 2026 issues | L6: https://www.exchange4media.com/people-movement-news/rochelle-pinto-is-head-of-editorial-content-for-vogue-india-130285.html | M6: Fit: Devyani (art and style feature, Neerja Birla template).
A7: 3 | B7: Rasna Bhasin | C7: Editor-in-Chief | D7: Harper's Bazaar India (India Today Group) | E7: Fashion, luxury, culture, art | F7: New Delhi | I7: Not in lists | J7: Verified - active 2026 | K7: Profiled as Editor-in-Chief (28 Apr 2026) | L7: https://www.hearstmagazinesinternational.com/news/off-the-page-with-rasna-bhasin-editor-in-chief-of-harpers-bazaar-india/ | M7: Fit: Devyani (collectors and culture coverage).
A8: 4 | B8: Che Kurrien | C8: Head of Editorial Content | D8: GQ India | E8: Men's lifestyle, culture, power lists | F8: Mumbai | I8: Not in lists | J8: Verified - active 2026 | K8: Listed as Head of Editorial Content, GQ India (Apr 2026) | L8: https://muckrack.com/che-kurrien/articles | M8: Fit: Devyani (GQ-type features named in brief).
A9: 5 | B9: Ainee Nizami Ahmedi | C9: Editor / Editorial Director | D9: Elle India | E9: Fashion, beauty, women | F9: Mumbai | I9: Not in lists | J9: To confirm | K9: Named Editor on Elle India pages; no dated 2026 evidence found | L9: https://elle.in/contact-us | M9: Your A & M list names Karuna Laungani as Elle editor; that is outdated.
A10: 6 | B10: Snigdha Ahuja | C10: Editor | D10: Cosmopolitan India (India Today Group) | E10: Fashion, beauty, pop culture | F10: New Delhi | I10: Not in lists | J10: Verified - current role | K10: Appointment as Editor, Cosmopolitan India (2025) | L10: https://www.exchange4media.com/media-print-news/snigdha-ahuja-appointed-as-new-editor-of-cosmopolitan-india-143224.html | M10: Fit: Devyani (women, motherhood, style).
A11: 7 | B11: Ambika Muttoo | C11: Editor-in-Chief | D11: Femina | E11: Women, lifestyle, achievers | F11: Mumbai | I11: Not in lists | J11: Verified - active 2026 | K11: Femina Beauty Awards 2026 jury (6 May 2026); leads Femina Achievers | L11: https://www.mediainfoline.com/awards/femina-beauty-awards-2026-ananya-panday-kriti-sanon-and-tamannaah-bhatia-lead-a-star-studded-night | M11: Fit: Devyani (Femina Achievers, women entrepreneurs, motherhood).
A12: 8 | B12: Shalini Umachandran | C12: Editor | D12: Mint Lounge | E12: Art, culture, lifestyle | I12: Not in lists | J12: Verified - current role | K12: Writes Mint Lounge's newsletter as editor (e.g. 'Unconditional love and AI') | L12: https://mintlounge.substack.com/p/unconditional-love-and-ai | M12: Brief names Mint Lounge as a target. Lead editor for a Devyani profile pitch.
A13: 9 | B13: Rahul Gangwani | C13: Editor-in-Chief | D13: Lifestyle Asia India (Burda Media India) | E13: Luxury lifestyle | F13: Mumbai | I13: Not in lists | J13: To confirm | K13: Listed as Editor-in-Chief on company page | L13: https://in.linkedin.com/company/lifestyle-asia-india | M13: Confirm before pitching.
A14: 10 | B14: Yilobeni Valerie Patton | C14: Features Editor | D14: Outlook Luxe | E14: Luxury, culture, people | F14: New Delhi | I14: Not in lists | J14: Verified - current role | K14: Named Features Editor on Outlook Luxe team page | L14: https://luxe.outlookindia.com/about-us | M14: Fit: Devyani (luxury lifestyle profile).
A15: 11 | B15: Priyamvada | C15: Senior Principal Correspondent | D15: Outlook Luxe | E15: Fashion, design, art, beauty, culture | F15: New Delhi | I15: Not in lists | J15: Verified - current role | K15: Named on Outlook Luxe team page | L15: https://luxe.outlookindia.com/about-us | M15: Fit: Devyani (art collection). Surname not listed on source.
A16: 12 | B16: Aalika Mahindra | C16: Editorial Director | D16: Verve | E16: Women, luxury lifestyle | F16: Mumbai | I16: Not in lists | J16: To confirm | K16: Listed as Editorial Director; no dated 2026 evidence | L16: https://en.wikipedia.org/wiki/Verve_(Indian_magazine) | M16: Confirm before pitching.
A17: 13 | B17: Bibek Bhattacharya | C17: National Editor, Mint; Deputy Editor, Mint Lounge | D17: Mint / Mint Lounge | E17: Arts, science, climate, culture | F17: New Delhi | I17: New research: contact to source | J17: Verified - current role | K17: Muck Rack and speaker profiles list him as Deputy Editor, Mint Lounge | L17: https://muckrack.com/bibek-bhattacharya/articles | M17: Fit: Devyani (Mint Lounge profile, art).
A18: 14 | B18: Divya Naik | C18: Writer | D18: Mint Lounge | E18: Women, work, motherhood | I18: New research: contact to source | J18: Verified - current role | K18: Mint Lounge pieces on the 'supermom' myth and women returning to work | L18: https://muckrack.com/media-outlet/lifestylelivemint | M18: Fit: Devyani (mother of three running education and healthcare ventures).
A19: 15 | B19: Seema Goswami | C19: Columnist ('Spectator', HT Brunch); host, 'Seema Says' (The Wire) | D19: Hindustan Times / The Wire | E19: Society, politics, culture | F19: New Delhi | I19: New research: contact to source | J19: Verified - active 2026 | K19: Hosts 'Seema Says' on The Wire (2026 episodes); weekly HT Brunch column | L19: https://thewire.in/government/seema-says-a-joyless-election-energy-woes-palantir-manifesto-and-wheres-the-football | M19: Fit: Devyani (women in public life, culture).
A20: 16 | B20: Shara Asraf | C20: National Editor, Lifestyle and Special Projects | D20: HT City (Hindustan Times) | E20: Lifestyle, fashion, Delhi events | F20: New Delhi | I20: New research: contact to source | J20: Verified - current role | K20: Muck Rack profile: National Editor, Lifestyle and Special Projects, HT City | L20: https://muckrack.com/shara-asraf | M20: Fit: Devyani (Delhi lifestyle, HT City features).
A21: 17 | B21: Veenu Singh | C21: Special Correspondent (arts and entertainment) | D21: Hindustan Times | E21: Arts, entertainment, lifestyle | F21: New Delhi | I21: New research: contact to source | J21: Verified - current role | K21: Muck Rack: HT Special Correspondent covering arts and entertainment | L21: https://muckrack.com/veenu-singh/articles | M21: Fit: Devyani art angle; Delhi cultural events.
A22: 18 | B22: Trisha Mukherjee | C22: Associate Editor | D22: The Indian Express | E22: Art, food, travel, books, features | F22: New Delhi | I22: New research: contact to source | J22: Verified - active 2026 | K22: Muck Rack: Associate Editor with 2026 articles on art, food and travel | L22: https://muckrack.com/trisha-mukherjee-2/articles | M22: Fit: Devyani art-collection feature.
A23: 19 | B23: Veenu Sandhu | C23: Senior Associate Editor (features) | D23: Business Standard | E23: Features, people, culture | F23: New Delhi | I23: New research: contact to source | J23: Verified - active 2026 | K23: Business Standard author page active Mar 2026 | L23: https://business-standard.com/author/veenu-sandhu | M23: Fit: Devyani business-and-life profile (BS Weekend).
A24: 20 | B24: Sadaf Shaikh | C24: Senior Features Editor | D24: Vogue India | E24: Features, culture | F24: Mumbai | I24: New research: contact to source | J24: Verified - current role | K24: Listed on Vogue India's Muck Rack page (2025-26 work) | L24: https://muckrack.com/sadaf-shaikh/articles | M24: Fit: Devyani feature with Vogue.
A25: 21 | B25: Akanksha Kamath | C25: Fashion Features Director | D25: Vogue India | E25: Fashion features | F25: Mumbai | I25: New research: contact to source | J25: Verified - current role | K25: Listed on Vogue India's Muck Rack page | L25: https://muckrack.com/akanksha-kamath | M25: Fit: Devyani style angle.
A26: 22 | B26: Kriti Shukla | C26: Features Writer | D26: Harper's Bazaar India | E26: Fashion, beauty, luxury | I26: New research: contact to source | J26: Verified - active 2026 | K26: Recent byline: 'The beauty trends from S/S 2026...' | L26: https://muckrack.com/kriti-shukla-1 | M26: Fit: Devyani luxury lifestyle.
A27: 23 | B27: Butool Jamal | C27: Fashion Features Editor | D27: Harper's Bazaar India | E27: Fashion features | I27: New research: contact to source | J27: Verified - current role | K27: Muck Rack profile at Harper's Bazaar India | L27: https://muckrack.com/butool-jamal/articles | M27: Fit: Devyani style angle.
A28: 24 | B28: Deepali Dhingra | C28: Freelance writer | D28: Freelance | E28: Lifestyle and entertainment | I28: New research: contact to source | J28: To confirm | K28: Muck Rack: freelance lifestyle and entertainment writer | L28: https://muckrack.com/deepali-singh-1 | M28: Confirm outlets before pitching.

Sheet Devyani - Celebrity & Society
A1: Devyani - Celebrity & Society
A2: FOR DEVYANI JAIPURIA ONLY. Celebrity, society and entertainment editors; use only with a celebrity or society hook.
A4: S.No | B4: Journalist Name | C4: Designation | D4: Organisation | E4: Beat / Vertical | F4: City | G4: Phone | H4: Email | I4: Contact Source (your lists) | J4: Verification Status | K4: Latest Activity Found | L4: Evidence Link | M4: Notes / Brand Fit
A5: 1 | B5: Ruchika Mehta | C5: Editor, HELLO! India; Editor, India Today Spice and Brides Today; Editor-at-Large, Luxury and Lifestyle | D5: India Today Group | E5: Celebrity, society, luxury, weddings | F5: New Delhi | G5: 9811156993 | H5: ruchikamehta05@gmail.com | I5: A & M Media List (Online sheet) | J5: Verified - active 2026 | K5: Took additional charge as Editor, India Today Spice (2026); IWD 2026 awardee as HELLO! Editor | L5: https://www.exchange4media.com/people-movement-news/ruchika-mehta-takes-additional-charge-as-editor-of-india-today-spice-158393.html | M5: Top fit for Devyani (HELLO! home/family/art feature). Old wwm.co.in email in your list is outdated; use gmail.
A6: 2 | B6: Sonal Kalra | C6: Chief Managing Editor, Entertainment and Lifestyle | D6: Hindustan Times (HT City) | E6: Entertainment, art, lifestyle (28 editions) | F6: New Delhi | I6: Not in lists | J6: Verified - active 2026 | K6: Season 3 of her HT show 'The Right Angle' premiered 20 Feb 2026; weekly HT City column | L6: https://www.exchange4media.com/announcements-news/sonal-kalra-to-launch-lifestyle-entertainment-news-show-142482.html | M6: Fit: Devyani (Delhi society, HT City).
A7: 3 | B7: Rohit Bhatnagar | C7: Entertainment Editor | D7: HT City, Delhi | E7: Celebrity interviews, entertainment | F7: New Delhi | I7: Not in lists | J7: Verified - current role | K7: Appointed Entertainment Editor, HT City Delhi (Aug 2025) | L7: https://www.exchange4media.com/people-movement-news/ht-city-delhi-appoints-rohit-bhatnagar-as-entertainment-editor-146845.html | M7: Fit: Devyani only with a celebrity hook (celebrity guests at her events).
A8: 4 | B8: Sneha Menon Desai | C8: Editor (from 1 Oct 2026) | D8: The Hollywood Reporter India | E8: Film, celebrity, entertainment business | F8: Mumbai | I8: Not in lists | J8: Verified - active 2026 | K8: Appointed Editor effective 1 Oct 2026, succeeding Anupama Chopra | L8: https://www.exchange4media.com/people-movement-news/sneha-menon-desai-appointed-editor-of-the-hollywood-reporter-india-158673.html | M8: Fit: Devyani only with a film or celebrity hook.
A9: 5 | B9: Madhureeta Mukherjee | C9: Editor | D9: Bombay Times (The Times of India) | E9: Celebrity, society, entertainment | F9: Mumbai | I9: Not in lists | J9: To confirm | K9: Quoted as Bombay Times editor (Dec 2024); no 2026 evidence found | L9: https://www.exchange4media.com/media-print-news/bombay-times-and-mumbais-symphony-a-30-year-partnership-139634.html | M9: Fit: Devyani society coverage if Mumbai events; confirm before use.
A10: 6 | B10: Gajendra Singh Bhati | C10: Entertainment Editor | D10: The Indian Express (Hindi) | E10: Entertainment, celebrity | F10: Noida | I10: Not in lists | J10: Verified - current role | K10: Joined Indian Express (Hindi) as Entertainment Editor after a decade at The Lallantop | L10: https://www.exchange4media.com/people-movement-news/gajendra-singh-bhati-joins-the-indian-express-hindi-as-entertainment-editor-154435.html | M10: Fit: Devyani only with a celebrity hook (Hindi reach).
A11: 7 | B11: Anindita Mukhopadhyay | C11: Chief Sub-Editor, leads Entertainment team | D11: India TV News | E11: Celebrity, entertainment | F11: Noida | I11: Not in lists | J11: Verified - current role | K11: India TV author page lists her as leading the entertainment team | L11: https://www.indiatvnews.com/author/anindita-mukhopadhyay/15 | M11: Fit: Devyani only with a celebrity hook (digital).
A12: 8 | B12: Mayank Shekhar | C12: Editorial Head, Entertainment; film critic | D12: Mid-day | E12: Film, celebrity, culture | F12: Mumbai | I12: New research: contact to source | J12: Verified - current role | K12: Editorial head of Mid-day entertainment; hosts 'Sit with Hitlist' | L12: https://www.exchange4media.com/media-print-news/mayank-shekhar-joins-mid-day-as-entertainment-head-65607.html | M12: Fit: Devyani only with a film or celebrity hook.
A13: 9 | B13: Nupur Sarvaiya | C13: Weddings Editor | D13: Vogue India | E13: Celebrity and society weddings | F13: Mumbai | I13: New research: contact to source | J13: Verified - current role | K13: Listed on Vogue India's Muck Rack page | L13: https://muckrack.com/nupur-sarvaiya/articles | M13: Fit: Devyani family or society events, only if cleared.

Sheet Devyani - Luxury, Art, Biz
A1: Devyani - Luxury, Art, Biz
A2: FOR DEVYANI JAIPURIA ONLY. Other outlets that suit Devyani: luxury, art-collector, home and business-profile writers.
A4: S.No | B4: Journalist Name | C4: Designation | D4: Organisation | E4: Beat / Vertical | F4: City | G4: Phone | H4: Email | I4: Contact Source (your lists) | J4: Verification Status | K4: Latest Activity Found | L4: Evidence Link | M4: Notes / Brand Fit
A5: 1 | B5: Pankti Mehta Kadakia | C5: Deputy Editor | D5: Forbes India | E5: Luxury, hospitality, culture, education | F5: Mumbai | G5: 9820741823 | H5: pankti.mehta@nw18.com; pankti.mehta@gmail.com | I5: A & M Media List; Education Media List | J5: Verified - active 2026 | K5: 2026 Forbes India bylines incl. AI and education; involved in 30 Under 30 2026 | L5: https://www.forbesindia.com/author/pankti-mehta-kadakia/5205 | M5: Fit: Devyani business profile; also DHS (education interest).
A6: 2 | B6: Aindrila Mitra | C6: Editor | D6: Robb Report India (RPSG Lifestyle Media) | E6: Luxury, collectors, lifestyle | F6: Kolkata/Mumbai | I6: Not in lists | J6: Verified - active 2026 | K6: Led Robb Report India first anniversary 'Chapter One: The Circle of Influence' (23-24 Aug 2026) | L6: https://www.esquireindia.co.in/food-and-drinks/what-to-eat/robb-report-india-turns-one-with-chapter-one-the-circle-of-influence-at-fairmont-udaipur-palace | M6: Fit: Devyani (art collection, luxury profile).
A7: 3 | B7: Shradha Shahani | C7: Managing Editor | D7: Robb Report India | E7: Luxury lifestyle | F7: Mumbai | I7: Not in lists | J7: Verified - current role | K7: Appointed Managing Editor, Robb Report India | L7: https://www.exchange4media.com/people-movement-news/robb-report-india-appoints-shradha-shahani-as-managing-editor-145291.html | M7: Same outlet as above.
A8: 4 | B8: Avantika Bhuyan | C8: Senior writer, art and culture (designation to confirm) | D8: Mint Lounge | E8: Contemporary art, design, culture | F8: New Delhi | G8: 09873631002 | H8: avantika.b@livemint.com; bhuyan.avantika@gmail.com | I8: Media List.xlsx (Financials sheet) | J8: Verified - current role | K8: Recent Mint Lounge art pieces (auto-narrative art, Sri Lankan artists, Sunder Nursery pavilion) | L8: https://muckrack.com/avantika-bhuyan/articles | M8: Top fit: Devyani art-collector story in Mint Lounge (named target in brief).
A9: 5 | B9: Akshaya Pillai | C9: Writer, culture and art | D9: Harper's Bazaar India | E9: Art, collectors, biennales | I9: Not in lists | J9: Verified - active 2026 | K9: Byline: 'Inside the minds of India's next-generation art collectors' (22 Jan 2026) | L9: https://www.harpersbazaar.in/authors/akshaya-pillai | M9: Top fit: Devyani as an art collector.
A10: 6 | B10: Dhamini Ratnam | C10: Journalist, art and culture | D10: Hindustan Times | E10: Art, culture | F10: New Delhi | I10: Not in lists | J10: Verified - active 2026 | K10: Covered India Art Fair 2026 (HT, 4 Feb 2026) | L10: https://www.pressreader.com/india/hindustan-times-st-noida/20260204/281767045655792 | M10: Fit: Devyani at India Art Fair or collection features.
A11: 7 | B11: Deboshri Bera | C11: Strategist (Art) | D11: Vogue India | E11: Art | F11: Mumbai | I11: Not in lists | J11: Verified - active 2026 | K11: Credited as Strategist (Art) in Vogue India Jan-Feb 2026 issue | L11: https://www.scribd.com/document/977838070/Vogue-India-January-February-2026 | M11: Fit: Devyani art angle with Vogue.
A12: 8 | B12: Bandana Tewari | C12: Freelance writer (former Vogue India Editor-at-Large) | D12: Architectural Digest India, Business of Fashion, NYT | E12: Art, craft, homes, fashion | I12: Not in lists | J12: Verified - active 2026 | K12: Wrote AD India's Jul-Aug 2026 cover story (Rajeev Sethi home-studio, Delhi) | L12: https://www.zinio.com/in/publications/architectural-digest-india/5361 | M12: Fit: Devyani home-and-art-collection feature (AD India).
A13: 9 | B13: Shrabonti Bagchi | C13: Independent writer (left Mint Lounge, Mar 2026) | D13: Freelance | E13: Features, culture, profiles | F13: Bengaluru (to confirm) | I13: Not in lists | J13: Moved - updated | K13: Last day at Mint as National Features Editor on 9 Mar 2026; now writing independently | L13: https://x.com/Shrabonti/status/2030894494447710494 | M13: Possible freelance commission for a long-form profile.
A14: 10 | B14: Suveen Sinha | C14: Editor | D14: Forbes India | E14: Business | F14: Mumbai | I14: Not in lists | J14: Verified - current role | K14: Forbes India editor; byline on W-Power series coverage | L14: https://muckrack.com/suveen-sinha/articles | M14: Forbes India W-Power 2026 list is a reference point for Devyani's business track.
A15: 11 | B15: Ela Das | C15: Editor | D15: Elle Decor India | E15: Design, homes, art | I15: New research: contact to source | J15: Verified - active 2026 | K15: Appointed Editor, Elle Decor India (24 Sep 2026); founding Digital Editor of AD India | L15: https://www.exchange4media.com/people-movement-news/elle-decor-india-appoints-ela-das-as-editor-158560.html | M15: Strong fit: Devyani home and art-collection feature.
A16: 12 | B16: Naini Thaker | C16: Journalist | D16: Forbes India | E16: Business, women leaders | F16: Mumbai | I16: New research: contact to source | J16: Verified - current role | K16: Muck Rack: Forbes India articles | L16: https://muckrack.com/naini-thaker/articles | M16: Fit: Devyani business track (W-Power style coverage).
A17: 13 | B17: Gayatri Sinha | C17: Art critic and curator | D17: Independent (wrote for The Hindu, Indian Express, The Telegraph) | E17: Contemporary Indian art | F17: New Delhi | I17: New research: contact to source | J17: To confirm | K17: Established Delhi art critic; current outlet to confirm | L17: https://en.wikipedia.org/wiki/Gayatri_Sinha | M17: Fit: Devyani art collection (critical voice, not staff).
A18: 14 | B18: Johny ML | C18: Cultural critic, curator and writer | D18: Independent | E18: Art, culture | F18: New Delhi | I18: New research: contact to source | J18: To confirm | K18: Delhi-based art critic; current outlet to confirm | L18: https://en.wikipedia.org/wiki/Johny_ML | M18: Fit: Devyani art angle (columns, art press).

Sheet DHS - Delhi NCR Education
A1: DHS - Delhi NCR Education
A2: Delhi NCR education journalists for Dharav High School, Gurugram (admissions season from October).
A4: S.No | B4: Journalist Name | C4: Designation | D4: Organisation | E4: Beat / Vertical | F4: City | G4: Phone | H4: Email | I4: Contact Source (your lists) | J4: Verification Status | K4: Latest Activity Found | L4: Evidence Link | M4: Notes / Brand Fit
A5: 1 | B5: Fareeha Iftikhar | C5: Assistant Editor, leads education coverage | D5: ThePrint | E5: Education (school and higher-ed policy) | F5: New Delhi | G5: 9560325287 | H5: fareeha.iftikhar@theprint.in; iftikharfareeha27@gmail.com | I5: Education Media List (ThePrint row); old HT row outdated | J5: Moved - updated | K5: Joined ThePrint Aug 2024 to lead education; writing on education in 2026 | L5: https://theprint.in/author/fareeha-iftikhar/ | M5: Do not use fareeha.iftikhar@htdigital.in (still in two of your lists).
A6: 2 | B6: Manash Pratim Gohain | C6: Senior Assistant Editor | D6: The Times of India | E6: Education policy (NEP, school and higher ed) | F6: New Delhi | G6: 9873685063 | H6: manash.gohain@timesgroup.com; manashpratimgohain@gmail.com | I6: Education Media List; Robust Education Media List | J6: Verified - active 2026 | K6: 20+ years on TOI education beat; NEP coverage referenced Jun 2026 | L6: https://journalarta.com/news/2026/06/29/manash-pratim-gohain-liputan-nep-2020/?all=1 | M6: Fit: DHS sports infrastructure + grassroots athlete policy (Khelo India, 2036 Olympics).
A7: 3 | B7: Priyanka Srivastava | C7: Senior Editor, Education Times | D7: The Times of India (Education Times) | E7: Education (national editor, 27 editions) | F7: New Delhi | G7: 9811861245 | H7: priyanka.srivastava@timesgroup.com | I7: Education Media List; Robust Education Media List | J7: Verified - current role | K7: Profile: Senior Editor, Education Times, TOI | L7: https://theorg.com/org/the-times-of-india/org-chart/priyanka-srivastava | M7: Fit: DHS principal interview (Ritu Jawa), admissions-season features.
A8: 4 | B8: Rajlakshmi Ghosh | C8: Senior Editor / Assistant Editor | D8: The Times of India (Education Times) | E8: School and higher education | F8: New Delhi / Faridabad | G8: 9810268942 | H8: rajlakshmi.ghosh@timesgroup.com | I8: Education Media List; Robust Education Media List | J8: Verified - current role | K8: Regular Education Times bylines on curriculum and school issues | L8: https://muckrack.com/rajlakshmi-ghosh/articles | M8: Fit: DHS curriculum and sports-integrated learning.
A9: 5 | B9: Sonal Srivastava | C9: Senior Assistant Editor | D9: The Times of India (Education Times) | E9: Education | F9: Noida | G9: 9871576637 / 9899927448 | H9: Sonal.Srivastava@timesgroup.com; srivastava.sonal296@gmail.com | I9: Education Media List; Robust Education Media List | J9: Verified - current role | K9: Education Times bylines and interviews (muckrack) | L9: https://muckrack.com/sonal-srivastava | M9: Two mobiles appear in your lists; confirm which is current.
A10: 6 | B10: Neeti Nigam | C10: Senior Assistant Editor, education vertical | D10: The Indian Express | E10: Education | F10: Noida | G10: 9899843905 | H10: neeti.nigam@indianexpress.com | I10: Education Media List; Robust Education Media List | J10: Verified - current role | K10: Senior Assistant Editor running IE's education vertical (LinkedIn, X) | L10: https://muckrack.com/neeti-nigam/articles | M10: Fit: DHS press releases and admissions stories.
A11: 7 | B11: Deeksha Teri | C11: Assistant Editor (education) | D11: Times Now News | E11: School governance, education policy, campus life | F11: New Delhi | G11: 8377977749 | I11: Robust Education Media List (IE email outdated) | J11: Moved - updated | K11: Muck Rack now lists her as Assistant Editor, Times Now News; previously Indian Express | L11: https://muckrack.com/deeksha-teri | M11: Do not use deeksha.teri@indianexpress.com. Mobile from old list; confirm.
A12: 8 | B12: Ritika Chopra | C12: Senior journalist, national bureau | D12: The Indian Express | E12: Governance, policy (covered Education Ministry) | F12: New Delhi | G12: 9810332214 | H12: ritika.chopra@expressindia.com | I12: Education Media List | J12: To confirm | K12: Long-time IE reporter on education ministry and Election Commission; current beat not confirmed | M12: Policy-level only; use for DHS grassroots-sport policy angle if she is still on education.
A13: 9 | B13: Prachi Verma | C13: Senior Assistant Editor | D13: The Economic Times | E13: HR and education | F13: New Delhi | G13: 9891002930 | H13: prachi.verma@timesgroup.com; prachi11atwork@gmail.com | I13: Education Media List; Robust Education Media List | J13: Verified - active 2026 | K13: Bylines on overseas study trends (Jan and Mar 2026) | L13: https://muckrack.com/prachivermaet/articles | M13: Fit: DHS founder or principal voice on future-ready schooling.
A14: 10 | B14: Abhishek Sahu | C14: Principal Correspondent | D14: The Economic Times | E14: HR and education | F14: New Delhi | G14: 9140230761 | I14: Education Media List; Robust Education Media List (Moneycontrol rows outdated) | J14: Moved - updated | K14: Now Principal Correspondent at ET covering HR and education; previously Moneycontrol | L14: https://muckrack.com/abhishek-sahu-2/articles | M14: Do not use Abhishek.Sahu@nw18.com. ET email not in your lists.
A15: 11 | B15: Puniti Pandey | C15: Senior Sub Editor, education | D15: NDTV | E15: Education (CBSE, boards, admissions) | F15: New Delhi | G15: 9560071458 | H15: punitip@ndtv.com; punitipandey.2@gmail.com | I15: Robust Education Media List; Education Media List | J15: Verified - active 2026 | K15: 2026 bylines on CBSE Board Exams 2026 and admissions | L15: https://muckrack.com/puniti-pandey/articles | M15: puniti.pandey@timesgroup.com in one list is an old address.
A16: 12 | B16: Sukanya Nandy | C16: Sub Editor, education | D16: CNN-News18 | E16: Education (exam results, CBSE, CUET) | F16: New Delhi | G16: 8527888004 | H16: sukanya.nandy@nw18.com; sukanyanandy15@gmail.com | I16: Education Media List; Robust Education Media List | J16: Verified - active 2026 | K16: Education desk at News18; profile active Feb 2026 | L16: https://intelligentrelations.com/journalist/sukanya-nandy/ | M16: Fit: DHS news releases.
A17: 13 | B17: Vatsala Shrangi | C17: Assistant Editor | D17: CNN-News18 | E17: Education policy (PM-SHRI, IITs, NEP) | F17: New Delhi | G17: 9999692270 | H17: Vatsala.Shrangi@ibnlive.com | I17: Robust Education Media List | J17: To confirm | K17: News18 education bylines; one 2025 source calls her 'formerly' a journalist | L17: https://buzzsumo.com/journalist/vatsala-shrangi-92753796/ | M17: Confirm she is still at News18.
A18: 14 | B18: Upasana Sharan | C18: Principal / Senior Copy Editor, education vertical | D18: BW Businessworld (BW Education) | E18: Education | F18: New Delhi | G18: 7739174388 | H18: upasana@businessworld.in; upasanasharan1995@gmail.com | I18: Education Media List; Robust Education Media List | J18: Verified - current role | K18: Handles BW Education vertical (author pages) | L18: http://bweducation.businessworld.in/author/BW-Reporters/Upasana-87081/ | M18: BW Education already carried DHS coverage; good repeat target.
A19: 15 | B19: Devina Sengupta | C19: Deputy Editor | D19: Mint | E19: HR, workplace, edtech | F19: Mumbai | G19: 9820463438 | H19: devina.sengupta@livemint.com; devinasengupta@gmail.com | I19: Robust Education Media List | J19: Verified - current role | K19: Listed as Deputy Editor, HR/workplace/edtech on Mint journalist directory | L19: https://muckrack.com/media-outlet/livemint | M19: Mumbai-based but national; Mint is the only national business daily on this sheet.
A20: 16 | B20: Sakshi Gupta | C20: Senior Content Developer | D20: Careers360 | E20: School education, students, teachers | F20: Ghaziabad (NCR) | G20: 9899997644 | I20: Education Media List (Free Press Journal row outdated) | J20: Moved - updated | K20: Careers360 author page; previously Free Press Journal | L20: https://news.careers360.com/author/sakshi-gupta | M20: Do not use sakshi@freepressjournal.in. Careers360 email not in your lists.
A21: 17 | B21: Nidhi Mittal | C21: Chief Sub Editor (English), education | D21: India TV | E21: Education | F21: New Delhi | G21: 8860628209 | H21: nidhimittal@indiatvnews.com; mittal.nidhi5@gmail.com | I21: Education Media List; Robust Education Media List | J21: To confirm | K21: India TV author page lists education stories; a LinkedIn profile shows a different employer | L21: https://www.indiatvnews.com/author/nidhi-mittal | M21: Confirm employer before use.
A22: 18 | B22: Smarica Pant | C22: Research Content Specialist | D22: India Today | E22: Digital content (education earlier) | F22: Noida | G22: 8587812356 | H22: smarica.pant@intoday.com | I22: Education Media List; Robust Education Media List | J22: To confirm | K22: Still at India Today per profile; current role not on education desk | L22: https://muckrack.com/smarica-pant | M22: Your list calls her Bureau Chief; that does not match her current profile.
A23: 19 | B23: Apoorva Anand | C23: Chief Sub Editor | D23: India Today | E23: Education (India Today Aspire earlier) | F23: Noida | G23: 9654773319 | H23: apoorva.intoday@gmail.com | I23: Robust Education Media List | J23: To confirm | K23: LinkedIn: Chief Sub Editor, India Today; education desk not confirmed | L23: https://www.linkedin.com/in/apoorva-anand-5b640046/ | M23: Confirm desk before use.
A24: 20 | B24: Charles Isaac | C24: Editor, HT Students' edition / News Editor | D24: Hindustan Times | E24: School edition (HT School) | F24: New Delhi | G24: 9717778709 | H24: charles.isaac@hindustantimes.com | I24: Education Media List; Robust Education Media List | J24: To confirm | K24: Could not confirm current role online | M24: HT School is a strong DHS outlet if he is still in the role; call to confirm.
A25: 21 | B25: Kritika Sharma | C25: Education correspondent (outlet to confirm) | D25: The Times of India / ThePrint (to confirm) | E25: Education | F25: New Delhi | G25: 8860752544 | H25: Kritika.Sharma@timesgroup.com | I25: Education Media List; Robust Education Media List | J25: To confirm | K25: Your lists show TOI; online author profile is from ThePrint | L25: https://theprint.in/author/kritika-sharma/ | M25: Confirm current outlet before use.
A26: 22 | B26: Zakariya Khan | C26: Senior Correspondent | D26: Financial Express | E26: Education | F26: New Delhi | G26: 7558378161 | H26: zakariya.khan@financialexpress.com | I26: Robust Education Media List | J26: To confirm | K26: Could not confirm online; one list row also shows a businessworld.in email | M26: Confirm current outlet before use.
A27: 23 | B27: Geetu Vaid | C27: Chief Sub Editor | D27: The Tribune | E27: Education, schools, careers features | F27: Chandigarh | G27: 9646878446 / 9501648446 | H27: geetu@tribunemail.com | I27: Education Media List; Robust Education Media List | J27: Verified - current role | K27: Tribune education and schools features (e.g. 'Extra Class' board-exam series) | L27: https://www.linkedin.com/in/geetu-vaid-05a926b4/ | M27: Chandigarh-based, not NCR; Tribune reaches Haryana families (Gurugram).
A28: 24 | B28: Sukrita Baruah | C28: Chief Reporter, Delhi city bureau | D28: The Indian Express | E28: Education and children, Delhi city | F28: New Delhi | I28: New research: contact to source | J28: Verified - active 2026 | K28: Took charge as Chief Reporter, Delhi bureau (Sep 2026); long record on education | L28: https://www.linkedin.com/in/sukrita-baruah-58aa77155/ | M28: Top fit: DHS (Delhi NCR education stories).
